{
  "nbformat": 4,
  "nbformat_minor": 0,
  "metadata": {
    "colab": {
      "provenance": [],
      "gpuType": "T4"
    },
    "kernelspec": {
      "name": "python3",
      "display_name": "Python 3"
    },
    "language_info": {
      "name": "python"
    },
    "accelerator": "GPU"
  },
  "cells": [
    {
      "cell_type": "code",
      "execution_count": null,
      "metadata": {
        "colab": {
          "base_uri": "https://localhost:8080/"
        },
        "id": "zY2hvAqBxf2q",
        "outputId": "fab1fc81-3700-48ab-d8f4-80712a9d3e02"
      },
      "outputs": [
        {
          "output_type": "stream",
          "name": "stdout",
          "text": [
            "Mounted at /content/drive\n"
          ]
        }
      ],
      "source": [
        "from google.colab import drive\n",
        "drive.mount('/content/drive')"
      ]
    },
    {
      "cell_type": "code",
      "source": [
        "!pip install evaluate\n",
        "!pip install accelerate -U\n",
        "!pip install datasets\n",
        "!git clone https://github.com/huggingface/transformers.git"
      ],
      "metadata": {
        "colab": {
          "base_uri": "https://localhost:8080/"
        },
        "id": "aZz5R0KTxrLu",
        "outputId": "7807b4c6-39ff-41ee-ec81-9896f68ad924"
      },
      "execution_count": null,
      "outputs": [
        {
          "output_type": "stream",
          "name": "stdout",
          "text": [
            "Requirement already satisfied: evaluate in /usr/local/lib/python3.10/dist-packages (0.4.1)\n",
            "Requirement already satisfied: datasets>=2.0.0 in /usr/local/lib/python3.10/dist-packages (from evaluate) (2.18.0)\n",
            "Requirement already satisfied: numpy>=1.17 in /usr/local/lib/python3.10/dist-packages (from evaluate) (1.25.2)\n",
            "Requirement already satisfied: dill in /usr/local/lib/python3.10/dist-packages (from evaluate) (0.3.8)\n",
            "Requirement already satisfied: pandas in /usr/local/lib/python3.10/dist-packages (from evaluate) (2.0.3)\n",
            "Requirement already satisfied: requests>=2.19.0 in /usr/local/lib/python3.10/dist-packages (from evaluate) (2.31.0)\n",
            "Requirement already satisfied: tqdm>=4.62.1 in /usr/local/lib/python3.10/dist-packages (from evaluate) (4.66.2)\n",
            "Requirement already satisfied: xxhash in /usr/local/lib/python3.10/dist-packages (from evaluate) (3.4.1)\n",
            "Requirement already satisfied: multiprocess in /usr/local/lib/python3.10/dist-packages (from evaluate) (0.70.16)\n",
            "Requirement already satisfied: fsspec[http]>=2021.05.0 in /usr/local/lib/python3.10/dist-packages (from evaluate) (2023.6.0)\n",
            "Requirement already satisfied: huggingface-hub>=0.7.0 in /usr/local/lib/python3.10/dist-packages (from evaluate) (0.20.3)\n",
            "Requirement already satisfied: packaging in /usr/local/lib/python3.10/dist-packages (from evaluate) (24.0)\n",
            "Requirement already satisfied: responses<0.19 in /usr/local/lib/python3.10/dist-packages (from evaluate) (0.18.0)\n",
            "Requirement already satisfied: filelock in /usr/local/lib/python3.10/dist-packages (from datasets>=2.0.0->evaluate) (3.13.3)\n",
            "Requirement already satisfied: pyarrow>=12.0.0 in /usr/local/lib/python3.10/dist-packages (from datasets>=2.0.0->evaluate) (14.0.2)\n",
            "Requirement already satisfied: pyarrow-hotfix in /usr/local/lib/python3.10/dist-packages (from datasets>=2.0.0->evaluate) (0.6)\n",
            "Requirement already satisfied: aiohttp in /usr/local/lib/python3.10/dist-packages (from datasets>=2.0.0->evaluate) (3.9.3)\n",
            "Requirement already satisfied: pyyaml>=5.1 in /usr/local/lib/python3.10/dist-packages (from datasets>=2.0.0->evaluate) (6.0.1)\n",
            "Requirement already satisfied: typing-extensions>=3.7.4.3 in /usr/local/lib/python3.10/dist-packages (from huggingface-hub>=0.7.0->evaluate) (4.10.0)\n",
            "Requirement already satisfied: charset-normalizer<4,>=2 in /usr/local/lib/python3.10/dist-packages (from requests>=2.19.0->evaluate) (3.3.2)\n",
            "Requirement already satisfied: idna<4,>=2.5 in /usr/local/lib/python3.10/dist-packages (from requests>=2.19.0->evaluate) (3.6)\n",
            "Requirement already satisfied: urllib3<3,>=1.21.1 in /usr/local/lib/python3.10/dist-packages (from requests>=2.19.0->evaluate) (2.0.7)\n",
            "Requirement already satisfied: certifi>=2017.4.17 in /usr/local/lib/python3.10/dist-packages (from requests>=2.19.0->evaluate) (2024.2.2)\n",
            "Requirement already satisfied: python-dateutil>=2.8.2 in /usr/local/lib/python3.10/dist-packages (from pandas->evaluate) (2.8.2)\n",
            "Requirement already satisfied: pytz>=2020.1 in /usr/local/lib/python3.10/dist-packages (from pandas->evaluate) (2023.4)\n",
            "Requirement already satisfied: tzdata>=2022.1 in /usr/local/lib/python3.10/dist-packages (from pandas->evaluate) (2024.1)\n",
            "Requirement already satisfied: aiosignal>=1.1.2 in /usr/local/lib/python3.10/dist-packages (from aiohttp->datasets>=2.0.0->evaluate) (1.3.1)\n",
            "Requirement already satisfied: attrs>=17.3.0 in /usr/local/lib/python3.10/dist-packages (from aiohttp->datasets>=2.0.0->evaluate) (23.2.0)\n",
            "Requirement already satisfied: frozenlist>=1.1.1 in /usr/local/lib/python3.10/dist-packages (from aiohttp->datasets>=2.0.0->evaluate) (1.4.1)\n",
            "Requirement already satisfied: multidict<7.0,>=4.5 in /usr/local/lib/python3.10/dist-packages (from aiohttp->datasets>=2.0.0->evaluate) (6.0.5)\n",
            "Requirement already satisfied: yarl<2.0,>=1.0 in /usr/local/lib/python3.10/dist-packages (from aiohttp->datasets>=2.0.0->evaluate) (1.9.4)\n",
            "Requirement already satisfied: async-timeout<5.0,>=4.0 in /usr/local/lib/python3.10/dist-packages (from aiohttp->datasets>=2.0.0->evaluate) (4.0.3)\n",
            "Requirement already satisfied: six>=1.5 in /usr/local/lib/python3.10/dist-packages (from python-dateutil>=2.8.2->pandas->evaluate) (1.16.0)\n",
            "Requirement already satisfied: accelerate in /usr/local/lib/python3.10/dist-packages (0.28.0)\n",
            "Requirement already satisfied: numpy>=1.17 in /usr/local/lib/python3.10/dist-packages (from accelerate) (1.25.2)\n",
            "Requirement already satisfied: packaging>=20.0 in /usr/local/lib/python3.10/dist-packages (from accelerate) (24.0)\n",
            "Requirement already satisfied: psutil in /usr/local/lib/python3.10/dist-packages (from accelerate) (5.9.5)\n",
            "Requirement already satisfied: pyyaml in /usr/local/lib/python3.10/dist-packages (from accelerate) (6.0.1)\n",
            "Requirement already satisfied: torch>=1.10.0 in /usr/local/lib/python3.10/dist-packages (from accelerate) (2.2.1+cu121)\n",
            "Requirement already satisfied: huggingface-hub in /usr/local/lib/python3.10/dist-packages (from accelerate) (0.20.3)\n",
            "Requirement already satisfied: safetensors>=0.3.1 in /usr/local/lib/python3.10/dist-packages (from accelerate) (0.4.2)\n",
            "Requirement already satisfied: filelock in /usr/local/lib/python3.10/dist-packages (from torch>=1.10.0->accelerate) (3.13.3)\n",
            "Requirement already satisfied: typing-extensions>=4.8.0 in /usr/local/lib/python3.10/dist-packages (from torch>=1.10.0->accelerate) (4.10.0)\n",
            "Requirement already satisfied: sympy in /usr/local/lib/python3.10/dist-packages (from torch>=1.10.0->accelerate) (1.12)\n",
            "Requirement already satisfied: networkx in /usr/local/lib/python3.10/dist-packages (from torch>=1.10.0->accelerate) (3.2.1)\n",
            "Requirement already satisfied: jinja2 in /usr/local/lib/python3.10/dist-packages (from torch>=1.10.0->accelerate) (3.1.3)\n",
            "Requirement already satisfied: fsspec in /usr/local/lib/python3.10/dist-packages (from torch>=1.10.0->accelerate) (2023.6.0)\n",
            "Requirement already satisfied: nvidia-cuda-nvrtc-cu12==12.1.105 in /usr/local/lib/python3.10/dist-packages (from torch>=1.10.0->accelerate) (12.1.105)\n",
            "Requirement already satisfied: nvidia-cuda-runtime-cu12==12.1.105 in /usr/local/lib/python3.10/dist-packages (from torch>=1.10.0->accelerate) (12.1.105)\n",
            "Requirement already satisfied: nvidia-cuda-cupti-cu12==12.1.105 in /usr/local/lib/python3.10/dist-packages (from torch>=1.10.0->accelerate) (12.1.105)\n",
            "Requirement already satisfied: nvidia-cudnn-cu12==8.9.2.26 in /usr/local/lib/python3.10/dist-packages (from torch>=1.10.0->accelerate) (8.9.2.26)\n",
            "Requirement already satisfied: nvidia-cublas-cu12==12.1.3.1 in /usr/local/lib/python3.10/dist-packages (from torch>=1.10.0->accelerate) (12.1.3.1)\n",
            "Requirement already satisfied: nvidia-cufft-cu12==11.0.2.54 in /usr/local/lib/python3.10/dist-packages (from torch>=1.10.0->accelerate) (11.0.2.54)\n",
            "Requirement already satisfied: nvidia-curand-cu12==10.3.2.106 in /usr/local/lib/python3.10/dist-packages (from torch>=1.10.0->accelerate) (10.3.2.106)\n",
            "Requirement already satisfied: nvidia-cusolver-cu12==11.4.5.107 in /usr/local/lib/python3.10/dist-packages (from torch>=1.10.0->accelerate) (11.4.5.107)\n",
            "Requirement already satisfied: nvidia-cusparse-cu12==12.1.0.106 in /usr/local/lib/python3.10/dist-packages (from torch>=1.10.0->accelerate) (12.1.0.106)\n",
            "Requirement already satisfied: nvidia-nccl-cu12==2.19.3 in /usr/local/lib/python3.10/dist-packages (from torch>=1.10.0->accelerate) (2.19.3)\n",
            "Requirement already satisfied: nvidia-nvtx-cu12==12.1.105 in /usr/local/lib/python3.10/dist-packages (from torch>=1.10.0->accelerate) (12.1.105)\n",
            "Requirement already satisfied: triton==2.2.0 in /usr/local/lib/python3.10/dist-packages (from torch>=1.10.0->accelerate) (2.2.0)\n",
            "Requirement already satisfied: nvidia-nvjitlink-cu12 in /usr/local/lib/python3.10/dist-packages (from nvidia-cusolver-cu12==11.4.5.107->torch>=1.10.0->accelerate) (12.4.127)\n",
            "Requirement already satisfied: requests in /usr/local/lib/python3.10/dist-packages (from huggingface-hub->accelerate) (2.31.0)\n",
            "Requirement already satisfied: tqdm>=4.42.1 in /usr/local/lib/python3.10/dist-packages (from huggingface-hub->accelerate) (4.66.2)\n",
            "Requirement already satisfied: MarkupSafe>=2.0 in /usr/local/lib/python3.10/dist-packages (from jinja2->torch>=1.10.0->accelerate) (2.1.5)\n",
            "Requirement already satisfied: charset-normalizer<4,>=2 in /usr/local/lib/python3.10/dist-packages (from requests->huggingface-hub->accelerate) (3.3.2)\n",
            "Requirement already satisfied: idna<4,>=2.5 in /usr/local/lib/python3.10/dist-packages (from requests->huggingface-hub->accelerate) (3.6)\n",
            "Requirement already satisfied: urllib3<3,>=1.21.1 in /usr/local/lib/python3.10/dist-packages (from requests->huggingface-hub->accelerate) (2.0.7)\n",
            "Requirement already satisfied: certifi>=2017.4.17 in /usr/local/lib/python3.10/dist-packages (from requests->huggingface-hub->accelerate) (2024.2.2)\n",
            "Requirement already satisfied: mpmath>=0.19 in /usr/local/lib/python3.10/dist-packages (from sympy->torch>=1.10.0->accelerate) (1.3.0)\n",
            "Requirement already satisfied: datasets in /usr/local/lib/python3.10/dist-packages (2.18.0)\n",
            "Requirement already satisfied: filelock in /usr/local/lib/python3.10/dist-packages (from datasets) (3.13.3)\n",
            "Requirement already satisfied: numpy>=1.17 in /usr/local/lib/python3.10/dist-packages (from datasets) (1.25.2)\n",
            "Requirement already satisfied: pyarrow>=12.0.0 in /usr/local/lib/python3.10/dist-packages (from datasets) (14.0.2)\n",
            "Requirement already satisfied: pyarrow-hotfix in /usr/local/lib/python3.10/dist-packages (from datasets) (0.6)\n",
            "Requirement already satisfied: dill<0.3.9,>=0.3.0 in /usr/local/lib/python3.10/dist-packages (from datasets) (0.3.8)\n",
            "Requirement already satisfied: pandas in /usr/local/lib/python3.10/dist-packages (from datasets) (2.0.3)\n",
            "Requirement already satisfied: requests>=2.19.0 in /usr/local/lib/python3.10/dist-packages (from datasets) (2.31.0)\n",
            "Requirement already satisfied: tqdm>=4.62.1 in /usr/local/lib/python3.10/dist-packages (from datasets) (4.66.2)\n",
            "Requirement already satisfied: xxhash in /usr/local/lib/python3.10/dist-packages (from datasets) (3.4.1)\n",
            "Requirement already satisfied: multiprocess in /usr/local/lib/python3.10/dist-packages (from datasets) (0.70.16)\n",
            "Requirement already satisfied: fsspec[http]<=2024.2.0,>=2023.1.0 in /usr/local/lib/python3.10/dist-packages (from datasets) (2023.6.0)\n",
            "Requirement already satisfied: aiohttp in /usr/local/lib/python3.10/dist-packages (from datasets) (3.9.3)\n",
            "Requirement already satisfied: huggingface-hub>=0.19.4 in /usr/local/lib/python3.10/dist-packages (from datasets) (0.20.3)\n",
            "Requirement already satisfied: packaging in /usr/local/lib/python3.10/dist-packages (from datasets) (24.0)\n",
            "Requirement already satisfied: pyyaml>=5.1 in /usr/local/lib/python3.10/dist-packages (from datasets) (6.0.1)\n",
            "Requirement already satisfied: aiosignal>=1.1.2 in /usr/local/lib/python3.10/dist-packages (from aiohttp->datasets) (1.3.1)\n",
            "Requirement already satisfied: attrs>=17.3.0 in /usr/local/lib/python3.10/dist-packages (from aiohttp->datasets) (23.2.0)\n",
            "Requirement already satisfied: frozenlist>=1.1.1 in /usr/local/lib/python3.10/dist-packages (from aiohttp->datasets) (1.4.1)\n",
            "Requirement already satisfied: multidict<7.0,>=4.5 in /usr/local/lib/python3.10/dist-packages (from aiohttp->datasets) (6.0.5)\n",
            "Requirement already satisfied: yarl<2.0,>=1.0 in /usr/local/lib/python3.10/dist-packages (from aiohttp->datasets) (1.9.4)\n",
            "Requirement already satisfied: async-timeout<5.0,>=4.0 in /usr/local/lib/python3.10/dist-packages (from aiohttp->datasets) (4.0.3)\n",
            "Requirement already satisfied: typing-extensions>=3.7.4.3 in /usr/local/lib/python3.10/dist-packages (from huggingface-hub>=0.19.4->datasets) (4.10.0)\n",
            "Requirement already satisfied: charset-normalizer<4,>=2 in /usr/local/lib/python3.10/dist-packages (from requests>=2.19.0->datasets) (3.3.2)\n",
            "Requirement already satisfied: idna<4,>=2.5 in /usr/local/lib/python3.10/dist-packages (from requests>=2.19.0->datasets) (3.6)\n",
            "Requirement already satisfied: urllib3<3,>=1.21.1 in /usr/local/lib/python3.10/dist-packages (from requests>=2.19.0->datasets) (2.0.7)\n",
            "Requirement already satisfied: certifi>=2017.4.17 in /usr/local/lib/python3.10/dist-packages (from requests>=2.19.0->datasets) (2024.2.2)\n",
            "Requirement already satisfied: python-dateutil>=2.8.2 in /usr/local/lib/python3.10/dist-packages (from pandas->datasets) (2.8.2)\n",
            "Requirement already satisfied: pytz>=2020.1 in /usr/local/lib/python3.10/dist-packages (from pandas->datasets) (2023.4)\n",
            "Requirement already satisfied: tzdata>=2022.1 in /usr/local/lib/python3.10/dist-packages (from pandas->datasets) (2024.1)\n",
            "Requirement already satisfied: six>=1.5 in /usr/local/lib/python3.10/dist-packages (from python-dateutil>=2.8.2->pandas->datasets) (1.16.0)\n",
            "fatal: destination path 'transformers' already exists and is not an empty directory.\n"
          ]
        }
      ]
    },
    {
      "cell_type": "code",
      "source": [
        "!python '/content/transformers/examples/pytorch/text-generation/run_generation.py' \\\n",
        "    --model_type=\"gpt2\" \\\n",
        "    --model_name_or_path=\"openai-community/gpt2\" \\\n",
        "    --prompt \"In a galaxy far, far away, there existed a powerful Jedi knight\" \\\n",
        "    --length 100 \\\n",
        "    --stop_token \"<END>\" \\\n",
        "    --temperature 0.7 \\\n",
        "    --repetition_penalty 2.0 \\\n",
        "    --k 50 \\\n",
        "    --p 0.9 \\\n",
        "    --prefix \"In a galaxy far, far away,\" \\\n",
        "    --padding_text \"A long time ago in a galaxy far, far away,\" \\\n",
        "    --xlm_language en \\\n",
        "    --seed 1337 \\\n",
        "    --num_return_sequences 5 \\\n",
        "    --fp16 \\\n",
        "    --jit"
      ],
      "metadata": {
        "colab": {
          "base_uri": "https://localhost:8080/"
        },
        "id": "cGjgCiK7LHls",
        "outputId": "b71732b4-2ae4-46e5-8417-ba48a87f8e19"
      },
      "execution_count": null,
      "outputs": [
        {
          "output_type": "stream",
          "name": "stdout",
          "text": [
            "04/04/2024 23:02:53 - WARNING - __main__ - device: cuda, 16-bits inference: True\n",
            "04/04/2024 23:02:54 - INFO - __main__ - Namespace(model_type='gpt2', model_name_or_path='openai-community/gpt2', prompt='In a galaxy far, far away, there existed a powerful Jedi knight', length=100, stop_token='<END>', temperature=0.7, repetition_penalty=2.0, k=50, p=0.9, prefix='In a galaxy far, far away,', padding_text='A long time ago in a galaxy far, far away,', xlm_language='en', seed=1337, use_cpu=False, num_return_sequences=5, fp16=True, jit=True)\n",
            "/usr/local/lib/python3.10/dist-packages/transformers/modeling_utils.py:4193: FutureWarning: `_is_quantized_training_enabled` is going to be deprecated in transformers 4.39.0. Please use `model.hf_quantizer.is_trainable` instead\n",
            "  warnings.warn(\n",
            "/usr/local/lib/python3.10/dist-packages/transformers/models/gpt2/modeling_gpt2.py:801: TracerWarning: Converting a tensor to a Python boolean might cause the trace to be incorrect. We can't record the data flow of Python values, so this value will be treated as a constant in the future. This means that the trace might not generalize to other inputs!\n",
            "  if batch_size <= 0:\n",
            "/usr/local/lib/python3.10/dist-packages/torch/jit/_trace.py:1102: TracerWarning: Output nr 1. of the traced function does not match the corresponding output of the Python function. Detailed error:\n",
            "Tensor-likes are not close!\n",
            "\n",
            "Mismatched elements: 136504 / 150771 (90.5%)\n",
            "Greatest absolute difference: 0.1875 at index (0, 1, 1448) (up to 1e-05 allowed)\n",
            "Greatest relative difference: 0.002390438247011952 at index (0, 2, 21580) (up to 1e-05 allowed)\n",
            "  _check_trace(\n",
            "The attention mask and the pad token id were not set. As a consequence, you may observe unexpected behavior. Please pass your input's `attention_mask` to obtain reliable results.\n",
            "Setting `pad_token_id` to `eos_token_id`:50256 for open-end generation.\n",
            "=== GENERATED SEQUENCE 1 ===\n",
            "2024-04-04 23:03:00.611230: E external/local_xla/xla/stream_executor/cuda/cuda_dnn.cc:9261] Unable to register cuDNN factory: Attempting to register factory for plugin cuDNN when one has already been registered\n",
            "2024-04-04 23:03:00.611286: E external/local_xla/xla/stream_executor/cuda/cuda_fft.cc:607] Unable to register cuFFT factory: Attempting to register factory for plugin cuFFT when one has already been registered\n",
            "2024-04-04 23:03:00.612694: E external/local_xla/xla/stream_executor/cuda/cuda_blas.cc:1515] Unable to register cuBLAS factory: Attempting to register factory for plugin cuBLAS when one has already been registered\n",
            "2024-04-04 23:03:01.699864: W tensorflow/compiler/tf2tensorrt/utils/py_utils.cc:38] TF-TRT Warning: Could not find TensorRT\n",
            "04/04/2024 23:03:02 - INFO - numexpr.utils - NumExpr defaulting to 2 threads.\n",
            "In a galaxy far, far away, there existed a powerful Jedi knight named Sith Lord Yoda who was in charge of the Great War. He had been defeated and taken prisoner by his fellow Knights during their final battle against Darth Vader's forces at Endor as well.[1]\n",
            "[16][17]\"I am an old man with great power that cannot be trusted.\" ―Darth Palpatine [src ]\n",
            "\n",
            "/Film Star Wars: The Clone Saga Edit<|endoftext|><|endoftext|><|endoftext|><|endoftext|><|endoftext|><|endoftext|><|endoftext|><|endoftext|><|endoftext|><|endoftext|><|endoftext|><|endoftext|><|endoftext|><|endoftext|><|endoftext|><|endoftext|><|endoftext|><|endoftext|><|endoftext|><|endoftext|\n",
            "=== GENERATED SEQUENCE 2 ===\n",
            "In a galaxy far, far away, there existed a powerful Jedi knight who commanded the Sith. He was known as \"The Dark One.\" This is one of his most famous images and has been widely used in films throughout history to illustrate how he came into being,\" said John Worthenstein Professor Emeritus at Harvard's Kennedy School for International Peace (KSP), an international organization that studies peacekeeping issues around world security by providing training programs or services directly from UAVs on missions such\n",
            "<|endoftext|><|endoftext|><|endoftext|><|endoftext|><|endoftext|><|endoftext|><|endoftext|><|endoftext|><|endoftext|><|endoftext|><|endoftext|><|endoftext|><|endoftext|><|endoftext|\n",
            "=== GENERATED SEQUENCE 3 ===\n",
            "In a galaxy far, far away, there existed a powerful Jedi knight and an evil Sith Lord. The dark side of the Force had been sealed shut in by that Dark Side Knight's secret weapon -- Darth Sidious' lightsaber! And now it was time for him to take out his enemies with this new light saber...\n",
            "I can't believe we're talking about one million years ago when he first took down these creatures who would have fought off Vader as they were not worthy victims but instead stood up against their own vile oppressors!\" ―Kylo Ren \n",
            "=== GENERATED SEQUENCE 4 ===\n",
            "In a galaxy far, far away, there existed a powerful Jedi knight named T'Aol who would take him to the Dark Side. He took his place as Master of Order and began teaching others how not only could they be trusted but that this was all part right! Now he has returned with many new friends - including Anderonians from other worlds such Ascalonian Empire or even Yavin 4-5 where one will surely find himself in battle against an Imperial officer!\" ―Bereto Anakin Skywalker [src]\n",
            "\"The Force is strong enoug\n",
            "=== GENERATED SEQUENCE 5 ===\n",
            "In a galaxy far, far away, there existed a powerful Jedi knight of the Order called Teth. He was one day destined to be an immortal being with powers beyond his imagination and he had no intention on leaving that world as soon after death but instead sought out Deathwing for aid in destroying him.\" ―Ladar Gogol [src]\n",
            " (TNG: \"The Bold One\") A number among those who worked alongside Dax Skywalker during their travels through time were Eriq Vostoevich or Lotharin Thulan.[\n"
          ]
        }
      ]
    },
    {
      "cell_type": "code",
      "source": [],
      "metadata": {
        "id": "i7xiO127MK61"
      },
      "execution_count": null,
      "outputs": []
    }
  ]
}